2025-05-02 15:32:37,351 - __main__ - ERROR - 加载模型出错: Unknown loss function: 'combined_loss'. Please ensure you are using a `keras.utils.custom_object_scope` and that this object is included in the scope. See https://www.tensorflow.org/guide/keras/save_and_serialize#registering_the_custom_object for details.
2025-05-02 15:32:37,352 - __main__ - ERROR - Traceback (most recent call last):
  File "D:\software\Investment-advisor\back_end\peudo_backend\prediction\model_predictor.py", line 136, in load_model
    self.model = load_model(str(model_file))
  File "D:\software\Python\explain\lib\site-packages\keras\utils\traceback_utils.py", line 70, in error_handler
    raise e.with_traceback(filtered_tb) from None
  File "D:\software\Python\explain\lib\site-packages\keras\saving\legacy\serialization.py", line 558, in deserialize_keras_object
    f"Unknown {printable_module_name}: '{object_name}'. "
ValueError: Unknown loss function: 'combined_loss'. Please ensure you are using a `keras.utils.custom_object_scope` and that this object is included in the scope. See https://www.tensorflow.org/guide/keras/save_and_serialize#registering_the_custom_object for details.

2025-05-02 15:32:37,677 - __main__ - ERROR - 加载模型出错: Unknown loss function: 'combined_loss'. Please ensure you are using a `keras.utils.custom_object_scope` and that this object is included in the scope. See https://www.tensorflow.org/guide/keras/save_and_serialize#registering_the_custom_object for details.
2025-05-02 15:32:37,678 - __main__ - ERROR - Traceback (most recent call last):
  File "D:\software\Investment-advisor\back_end\peudo_backend\prediction\model_predictor.py", line 136, in load_model
    self.model = load_model(str(model_file))
  File "D:\software\Python\explain\lib\site-packages\keras\utils\traceback_utils.py", line 70, in error_handler
    raise e.with_traceback(filtered_tb) from None
  File "D:\software\Python\explain\lib\site-packages\keras\saving\legacy\serialization.py", line 558, in deserialize_keras_object
    f"Unknown {printable_module_name}: '{object_name}'. "
ValueError: Unknown loss function: 'combined_loss'. Please ensure you are using a `keras.utils.custom_object_scope` and that this object is included in the scope. See https://www.tensorflow.org/guide/keras/save_and_serialize#registering_the_custom_object for details.

2025-05-02 15:32:37,678 - __main__ - ERROR - 模型未加载
